<robot
  name="humanoid_new_feet">
  <link
    name="torso">
    <inertial>
      <origin
        xyz="-0.012931 -7.2787E-11 0.49048"
        rpy="0 0 0" />
      <mass
        value="1.548" />
      <inertia
        ixx="0.0068059"
        ixy="1.2392E-11"
        ixz="0.00082079"
        iyy="0.0070134"
        iyz="1.3089E-11"
        izz="0.0024113" />
    </inertial>
    <visual>
      <origin
        xyz="0 0 0"
        rpy="0 0 0" />
      <geometry>
        <mesh
          filename="meshes_new/torso.STL" />
      </geometry>
      <material
        name="">
        <color
          rgba="0.75294 0.75294 0.75294 1" />
      </material>
    </visual>
    <collision>
      <origin
        xyz="0 0 0"
        rpy="0 0 0" />
      <geometry>
        <mesh
          filename="meshes_new/torso.STL" />
      </geometry>
    </collision>
  </link>
  <link
    name="head_p">
    <inertial>
      <origin
        xyz="-8.3267E-17 5.5511E-17 -0.023536"
        rpy="0 0 0" />
      <mass
        value="0.0091975" />
      <inertia
        ixx="0"
        ixy="0"
        ixz="0"
        iyy="0"
        iyz="0"
        izz="0" />
    </inertial>
    <visual>
      <origin
        xyz="0 0 0"
        rpy="0 0 0" />
      <geometry>
        <mesh
          filename="meshes_new/head_p.STL" />
      </geometry>
      <material
        name="">
        <color
          rgba="0.89804 0.91765 0.92941 1" />
      </material>
    </visual>
    <collision>
      <origin
        xyz="0 0 0"
        rpy="0 0 0" />
      <geometry>
        <mesh
          filename="meshes_new/head_p.STL" />
      </geometry>
    </collision>
  </link>
  <joint
    name="j_head_p"
    type="revolute">
    <origin
      xyz="0.0265 0 0.64896"
      rpy="9.1445E-16 1.3244E-15 7.7716E-16" />
    <parent
      link="torso" />
    <child
      link="head_p" />
    <axis
      xyz="0 0 1" />
    <limit
      lower="-1.57"
      upper="1.57"
      effort="8.4"
      velocity="1.5" />
  </joint>
  <link
    name="head_t">
    <inertial>
      <origin
        xyz="1.2365E-09 2.327E-05 0.01114"
        rpy="0 0 0" />
      <mass
        value="0.073123" />
      <inertia
        ixx="1.2201E-06"
        ixy="-9.1137E-13"
        ixz="4.9259E-13"
        iyy="3.0718E-07"
        iyz="4.3038E-08"
        izz="9.1291E-07" />
    </inertial>
    <visual>
      <origin
        xyz="0 0 0"
        rpy="0 0 0" />
      <geometry>
        <mesh
          filename="meshes_new/head_t.STL" />
      </geometry>
      <material
        name="">
        <color
          rgba="0.75294 0.75294 0.75294 1" />
      </material>
    </visual>
    <collision>
      <origin
        xyz="0 0 0"
        rpy="0 0 0" />
      <geometry>
        <mesh
          filename="meshes_new/head_t.STL" />
      </geometry>
    </collision>
  </link>
  <joint
    name="j_head_t"
    type="revolute">
    <origin
      xyz="0 -0.00025 0"
      rpy="1.4381E-16 -9.993E-17 -7.2164E-16" />
    <parent
      link="head_p" />
    <child
      link="head_t" />
    <axis
      xyz="0 1 0" />
    <limit
      lower="-1.57"
      upper="1.57"
      effort="8.4"
      velocity="1.5" />
  </joint>
  <link
    name="leg_r_hip_y">
    <inertial>
      <origin
        xyz="-0.019 2.7756E-17 0.029685"
        rpy="0 0 0" />
      <mass
        value="0.031031" />
      <inertia
        ixx="0"
        ixy="0"
        ixz="0"
        iyy="0"
        iyz="0"
        izz="0" />
    </inertial>
    <visual>
      <origin
        xyz="0 0 0"
        rpy="0 0 0" />
      <geometry>
        <mesh
          filename="meshes_new/leg_r_hip_y.STL" />
      </geometry>
      <material
        name="">
        <color
          rgba="0.89804 0.91765 0.92941 1" />
      </material>
    </visual>
    <collision>
      <origin
        xyz="0 0 0"
        rpy="0 0 0" />
      <geometry>
        <mesh
          filename="meshes_new/leg_r_hip_y.STL" />
      </geometry>
    </collision>
  </link>
  <joint
    name="j_leg_r_hip_y"
    type="revolute">
    <origin
      xyz="0.019 -0.06125 0.315"
      rpy="8.9196E-17 1.0628E-15 6.6613E-16" />
    <parent
      link="torso" />
    <child
      link="leg_r_hip_y" />
    <axis
      xyz="0 0 -1" />
    <limit
      lower="-1.57"
      upper="1.57"
      effort="16"
      velocity="3" />
  </joint>
  <link
    name="leg_r_hip_r">
    <inertial>
      <origin
        xyz="-0.0199386687185207 8.18687657398315E-05 -0.0148029206019012"
        rpy="0 0 0" />
      <mass
        value="0.327163613554732" />
      <inertia
        ixx="7.62597233459812E-06"
        ixy="-5.58485045961204E-07"
        ixz="-1.06787658576979E-05"
        iyy="0.000186208050229139"
        iyz="-1.51343403230769E-06"
        izz="0.000185497017404406" />
    </inertial>
    <visual>
      <origin
        xyz="0 0 0"
        rpy="0 0 0" />
      <geometry>
        <mesh
          filename="meshes_new/leg_r_hip_r.STL" />
      </geometry>
      <material
        name="">
        <color
          rgba="0.752941176470588 0.752941176470588 0.752941176470588 1" />
      </material>
    </visual>
    <collision>
      <origin
        xyz="0 0 0"
        rpy="0 0 0" />
      <geometry>
        <mesh
          filename="meshes_new/leg_r_hip_r.STL" />
      </geometry>
    </collision>
  </link>
  <joint
    name="j_leg_r_hip_r"
    type="revolute">
    <origin
      xyz="0.0005 0 0"
      rpy="1.1312E-16 -2.6124E-16 1.1102E-16" />
    <parent
      link="leg_r_hip_y" />
    <child
      link="leg_r_hip_r" />
    <axis
      xyz="1 0 0" />
    <limit
      lower="-1.57"
      upper="1.57"
      effort="16"
      velocity="3" />
  </joint>
  <link
    name="leg_r_hip_p">
    <inertial>
      <origin
        xyz="-4.7361E-05 0.00014667 -0.10143"
        rpy="0 0 0" />
      <mass
        value="0.18783" />
      <inertia
        ixx="9.8966E-05"
        ixy="-1.5606E-09"
        ixz="2.1853E-07"
        iyy="9.6525E-05"
        iyz="1.7817E-06"
        izz="2.459E-06" />
    </inertial>
    <visual>
      <origin
        xyz="0 0 0"
        rpy="0 0 0" />
      <geometry>
        <mesh
          filename="meshes_new/leg_r_hip_p.STL" />
      </geometry>
      <material
        name="">
        <color
          rgba="0.75294 0.75294 0.75294 1" />
      </material>
    </visual>
    <collision>
      <origin
        xyz="0 0 0"
        rpy="0 0 0" />
      <geometry>
        <mesh
          filename="meshes_new/leg_r_hip_p.STL" />
      </geometry>
    </collision>
  </link>
  <joint
    name="j_leg_r_hip_p"
    type="revolute">
    <origin
      xyz="0 0 0"
      rpy="-3.6978E-32 2.4326E-16 0" />
    <parent
      link="leg_r_hip_r" />
    <child
      link="leg_r_hip_p" />
    <axis
      xyz="0 -1 0" />
    <limit
      lower="-1.57"
      upper="1.57"
      effort="16"
      velocity="3" />
  </joint>
  <link
    name="leg_r_knee">
    <inertial>
      <origin
        xyz="6.10622663543836E-16 -4.16333634234434E-17 -0.0720000000000057"
        rpy="0 0 0" />
      <mass
        value="0.047124436448338" />
      <inertia
        ixx="3.47240331970277E-05"
        ixy="-2.5410988417629E-21"
        ixz="6.83174378432935E-21"
        iyy="3.47240295022833E-05"
        iyz="-1.13268007040626E-08"
        izz="3.69474441844712E-12" />
    </inertial>
    <visual>
      <origin
        xyz="0 0 0"
        rpy="0 0 0" />
      <geometry>
        <mesh
          filename="meshes_new/leg_r_knee.STL" />
      </geometry>
      <material
        name="">
        <color
          rgba="0.752941176470588 0.752941176470588 0.752941176470588 1" />
      </material>
    </visual>
    <collision>
      <origin
        xyz="0 0 0"
        rpy="0 0 0" />
      <geometry>
        <mesh
          filename="meshes_new/leg_r_knee.STL" />
      </geometry>
    </collision>
  </link>
  <joint
    name="j_leg_r_knee"
    type="revolute">
    <origin
      xyz="0 0 -0.1265"
      rpy="-2.0065E-17 -3.0531E-16 4.4409E-16" />
    <parent
      link="leg_r_hip_p" />
    <child
      link="leg_r_knee" />
    <axis
      xyz="0 -1 0" />
    <limit
      lower="-3.14"
      upper="3.14"
      effort="16"
      velocity="3" />
  </joint>
  <link
    name="leg_r_ankle_p">
    <inertial>
      <origin
        xyz="-0.019967776162788 8.53120662437229E-05 0.0148115628962607"
        rpy="0 0 0" />
      <mass
        value="0.326972717692244" />
      <inertia
        ixx="7.5839311314915E-06"
        ixy="-5.32558183370191E-07"
        ixz="1.05552671788852E-05"
        iyy="0.000185755819336967"
        iyz="1.51216193590398E-06"
        izz="0.000185086453835138" />
    </inertial>
    <visual>
      <origin
        xyz="0 0 0"
        rpy="0 0 0" />
      <geometry>
        <mesh
          filename="meshes_new/leg_r_ankle_p.STL" />
      </geometry>
      <material
        name="">
        <color
          rgba="0.752941176470588 0.752941176470588 0.752941176470588 1" />
      </material>
    </visual>
    <collision>
      <origin
        xyz="0 0 0"
        rpy="0 0 0" />
      <geometry>
        <mesh
          filename="meshes_new/leg_r_ankle_p.STL" />
      </geometry>
    </collision>
  </link>
  <joint
    name="j_leg_r_ankle_p"
    type="revolute">
    <origin
      xyz="0 0 -0.144"
      rpy="-7.2967E-17 1.2589E-15 -5.5511E-16" />
    <parent
      link="leg_r_knee" />
    <child
      link="leg_r_ankle_p" />
    <axis
      xyz="0 1 0" />
    <limit
      lower="-1.57"
      upper="1.57"
      effort="16"
      velocity="3" />
  </joint>
  <link
    name="leg_r_ankle_r">
    <inertial>
      <origin
        xyz="-0.0195 -4.16333634234434E-17 -0.0376287953896525"
        rpy="0 0 0" />
      <mass
        value="0.110581863873309" />
      <inertia
        ixx="2.98180362687765E-06"
        ixy="-5.29395592033938E-22"
        ixz="-2.28751636133055E-20"
        iyy="2.98180362687765E-06"
        iyz="-1.32858912118433E-20"
        izz="1.39263961851025E-33" />
    </inertial>
    <visual>
      <origin
        xyz="0 0 0"
        rpy="0 0 0" />
      <geometry>
        <mesh
          filename="meshes_new/leg_r_ankle_r.STL" />
      </geometry>
      <material
        name="">
        <color
          rgba="0.752941176470588 0.752941176470588 0.752941176470588 1" />
      </material>
    </visual>
    <collision>
      <origin
        xyz="0 0 0"
        rpy="0 0 0" />
      <geometry>
        <mesh
          filename="meshes_new/leg_r_ankle_r.STL" />
      </geometry>
    </collision>
  </link>
  <joint
    name="j_leg_r_ankle_r"
    type="revolute">
    <origin
      xyz="0 0 0"
      rpy="2.3592E-16 -1.9984E-15 -6.1062E-16" />
    <parent
      link="leg_r_ankle_p" />
    <child
      link="leg_r_ankle_r" />
    <axis
      xyz="-1 0 0" />
    <limit
      lower="-1.57"
      upper="1.57"
      effort="16"
      velocity="3" />
  </joint>

<!--link
    name="leg_r_foot">
    <inertial>
      <origin
        xyz="0 0 0"
        rpy="0 0 0" />
      <mass
        value="0" />
      <inertia
        ixx="0"
        ixy="0"
        ixz="0"
        iyy="0"
        iyz="0"
        izz="0" />
    </inertial>
  </link>
  <joint
    name="j_leg_r_foot"
    type="fixed">
    <origin
      xyz="-0.0195 0 -0.0445"
      rpy="0 0 0" />
    <parent
      link="leg_r_ankle_r" />
    <child
      link="leg_r_foot" />
  </joint-->

  <link
    name="leg_l_hip_y">
    <inertial>
      <origin
        xyz="-0.019 2.7756E-17 0.029685"
        rpy="0 0 0" />
      <mass
        value="0.031031" />
      <inertia
        ixx="0"
        ixy="0"
        ixz="0"
        iyy="0"
        iyz="0"
        izz="0" />
    </inertial>
    <visual>
      <origin
        xyz="0 0 0"
        rpy="0 0 0" />
      <geometry>
        <mesh
          filename="meshes_new/leg_l_hip_y.STL" />
      </geometry>
      <material
        name="">
        <color
          rgba="0.89804 0.91765 0.92941 1" />
      </material>
    </visual>
    <collision>
      <origin
        xyz="0 0 0"
        rpy="0 0 0" />
      <geometry>
        <mesh
          filename="meshes_new/leg_l_hip_y.STL" />
      </geometry>
    </collision>
  </link>
  <joint
    name="j_leg_l_hip_y"
    type="revolute">
    <origin
      xyz="0.019 0.06125 0.315"
      rpy="1.6077E-16 9.6944E-16 5.5511E-16" />
    <parent
      link="torso" />
    <child
      link="leg_l_hip_y" />
    <axis
      xyz="0 0 -1" />
    <limit
      lower="-1.57"
      upper="1.57"
      effort="16"
      velocity="3" />
  </joint>
  <link
    name="leg_l_hip_r">
    <inertial>
      <origin
        xyz="-0.019939 8.1869E-05 -0.014803"
        rpy="0 0 0" />
      <mass
        value="0.32716" />
      <inertia
        ixx="7.626E-06"
        ixy="-5.5849E-07"
        ixz="-1.0679E-05"
        iyy="0.00018621"
        iyz="-1.5134E-06"
        izz="0.0001855" />
    </inertial>
    <visual>
      <origin
        xyz="0 0 0"
        rpy="0 0 0" />
      <geometry>
        <mesh
          filename="meshes_new/leg_l_hip_r.STL" />
      </geometry>
      <material
        name="">
        <color
          rgba="0.75294 0.75294 0.75294 1" />
      </material>
    </visual>
    <collision>
      <origin
        xyz="0 0 0"
        rpy="0 0 0" />
      <geometry>
        <mesh
          filename="meshes_new/leg_l_hip_r.STL" />
      </geometry>
    </collision>
  </link>
  <joint
    name="j_leg_l_hip_r"
    type="revolute">
    <origin
      xyz="0.0005 0 0"
      rpy="1.1312E-16 -2.6124E-16 1.1102E-16" />
    <parent
      link="leg_l_hip_y" />
    <child
      link="leg_l_hip_r" />
    <axis
      xyz="1 0 0" />
    <limit
      lower="-1.57"
      upper="1.57"
      effort="16"
      velocity="3" />
  </joint>
  <link
    name="leg_l_hip_p">
    <inertial>
      <origin
        xyz="-4.7361E-05 0.00014667 -0.10143"
        rpy="0 0 0" />
      <mass
        value="0.18783" />
      <inertia
        ixx="9.8966E-05"
        ixy="-1.5606E-09"
        ixz="2.1853E-07"
        iyy="9.6525E-05"
        iyz="1.7817E-06"
        izz="2.459E-06" />
    </inertial>
    <visual>
      <origin
        xyz="0 0 0"
        rpy="0 0 0" />
      <geometry>
        <mesh
          filename="meshes_new/leg_l_hip_p.STL" />
      </geometry>
      <material
        name="">
        <color
          rgba="0.75294 0.75294 0.75294 1" />
      </material>
    </visual>
    <collision>
      <origin
        xyz="0 0 0"
        rpy="0 0 0" />
      <geometry>
        <mesh
          filename="meshes_new/leg_l_hip_p.STL" />
      </geometry>
    </collision>
  </link>
  <joint
    name="j_leg_l_hip_p"
    type="revolute">
    <origin
      xyz="0 0 0"
      rpy="-1.1312E-16 2.3351E-16 -5.5511E-17" />
    <parent
      link="leg_l_hip_r" />
    <child
      link="leg_l_hip_p" />
    <axis
      xyz="0 -1 0" />
    <limit
      lower="-1.57"
      upper="1.57"
      effort="16"
      velocity="3" />
  </joint>
  <link
    name="leg_l_knee">
    <inertial>
      <origin
        xyz="5.5511E-16 1.6653E-16 -0.072"
        rpy="0 0 0" />
      <mass
        value="0.047124" />
      <inertia
        ixx="3.4724E-05"
        ixy="0"
        ixz="6.119E-21"
        iyy="3.4724E-05"
        iyz="-1.1327E-08"
        izz="3.6947E-12" />
    </inertial>
    <visual>
      <origin
        xyz="0 0 0"
        rpy="0 0 0" />
      <geometry>
        <mesh
          filename="meshes_new/leg_l_knee.STL" />
      </geometry>
      <material
        name="">
        <color
          rgba="0.75294 0.75294 0.75294 1" />
      </material>
    </visual>
    <collision>
      <origin
        xyz="0 0 0"
        rpy="0 0 0" />
      <geometry>
        <mesh
          filename="meshes_new/leg_l_knee.STL" />
      </geometry>
    </collision>
  </link>
  <joint
    name="j_leg_l_knee"
    type="revolute">
    <origin
      xyz="0 0 -0.1265"
      rpy="2.6064E-17 -3.4694E-16 6.1062E-16" />
    <parent
      link="leg_l_hip_p" />
    <child
      link="leg_l_knee" />
    <axis
      xyz="0 -1 0" />
    <limit
      lower="-3.14"
      upper="3.14"
      effort="16"
      velocity="3" />
  </joint>
  <link
    name="leg_l_ankle_p">
    <inertial>
      <origin
        xyz="-0.019968 8.5312E-05 0.014812"
        rpy="0 0 0" />
      <mass
        value="0.32697" />
      <inertia
        ixx="7.5839E-06"
        ixy="-5.3256E-07"
        ixz="1.0555E-05"
        iyy="0.00018576"
        iyz="1.5122E-06"
        izz="0.00018509" />
    </inertial>
    <visual>
      <origin
        xyz="0 0 0"
        rpy="0 0 0" />
      <geometry>
        <mesh
          filename="meshes_new/leg_l_ankle_p.STL" />
      </geometry>
      <material
        name="">
        <color
          rgba="0.75294 0.75294 0.75294 1" />
      </material>
    </visual>
    <collision>
      <origin
        xyz="0 0 0"
        rpy="0 0 0" />
      <geometry>
        <mesh
          filename="meshes_new/leg_l_ankle_p.STL" />
      </geometry>
    </collision>
  </link>
  <joint
    name="j_leg_l_ankle_p"
    type="revolute">
    <origin
      xyz="0 0 -0.144"
      rpy="-3.8286E-16 1.1538E-15 -5.5511E-16" />
    <parent
      link="leg_l_knee" />
    <child
      link="leg_l_ankle_p" />
    <axis
      xyz="0 1 0" />
    <limit
      lower="-1.57"
      upper="1.57"
      effort="16"
      velocity="3" />
  </joint>
  <link
    name="leg_l_ankle_r">
    <inertial>
      <origin
        xyz="-0.0195 5.5511E-17 -0.037629"
        rpy="0 0 0" />
      <mass
        value="0.11058" />
      <inertia
        ixx="2.9818E-06"
        ixy="0"
        ixz="-6.7503E-20"
        iyy="2.9818E-06"
        iyz="-3.2314E-20"
        izz="3.2165E-33" />
    </inertial>
    <visual>
      <origin
        xyz="0 0 0"
        rpy="0 0 0" />
      <geometry>
        <mesh
          filename="meshes_new/leg_l_ankle_r.STL" />
      </geometry>
      <material
        name="">
        <color
          rgba="0.75294 0.75294 0.75294 1" />
      </material>
    </visual>
    <collision>
      <origin
        xyz="0 0 0"
        rpy="0 0 0" />
      <geometry>
        <mesh
          filename="meshes_new/leg_l_ankle_r.STL" />
      </geometry>
    </collision>
  </link>
  <joint
    name="j_leg_l_ankle_r"
    type="revolute">
    <origin
      xyz="0 0 0"
      rpy="1.9602E-16 -1.8319E-15 -8.8818E-16" />
    <parent
      link="leg_l_ankle_p" />
    <child
      link="leg_l_ankle_r" />
    <axis
      xyz="-1 0 0" />
    <limit
      lower="-1.57"
      upper="1.57"
      effort="16"
      velocity="3" />
  </joint>

<!--link
    name="leg_l_foot">
    <inertial>
      <origin
        xyz="0 0 0"
        rpy="0 0 0" />
      <mass
        value="0" />
      <inertia
        ixx="0"
        ixy="0"
        ixz="0"
        iyy="0"
        iyz="0"
        izz="0" />
    </inertial>
  </link>
  <joint
    name="j_leg_l_foot"
    type="fixed">
    <origin
      xyz="-0.0195 0 -0.0445"
      rpy="0 0 0" />
    <parent
      link="leg_l_ankle_r" />
    <child
      link="leg_l_foot" />
  </joint-->
</robot>