<?xml version="1.0" encoding="utf-8"?>
<!-- This URDF was automatically created by SolidWorks to URDF Exporter! Originally created by Stephen Brawner (brawner@gmail.com) 
     Commit Version: 1.5.0-0-g9aa0fdb  Build Version: 1.5.7004.21443
     For more information, please see http://wiki.ros.org/sw_urdf_exporter -->
<robot
  name="main_new_feet_no_arm_update_motor">
  <link
    name="torso">
    <inertial>
      <origin
        xyz="-0.01281 -1E-05 0.48997"
        rpy="0 0 0" />
      <mass
        value="1.558" />
      <inertia
        ixx="0.0037818"
        ixy="6.95E-12"
        ixz="-3.05E-07"
        iyy="0.0022099"
        iyz="-8.01E-13"
        izz="0.0020099" />
    </inertial>
    <visual>
      <origin
        xyz="0 0 0"
        rpy="0 0 0" />
      <geometry>
        <mesh
          filename="package://main_new_feet_no_arm_update_motor/meshes/torso.STL" />
      </geometry>
      <material
        name="">
        <color
          rgba="0.75294 0.75294 0.75294 1" />
      </material>
    </visual>
    <collision>
      <origin
        xyz="0 0 0"
        rpy="0 0 0" />
      <geometry>
        <mesh
          filename="package://main_new_feet_no_arm_update_motor/meshes/torso.STL" />
      </geometry>
    </collision>
  </link>
  <link
    name="head_p">
    <inertial>
      <origin
        xyz="0 0 -0.023536"
        rpy="0 0 0" />
      <mass
        value="0.0091975" />
      <inertia
        ixx="3.69E-06"
        ixy="1.59E-22"
        ixz="1.56E-21"
        iyy="1.5E-06"
        iyz="-3.97E-21"
        izz="3.35E-06" />
    </inertial>
    <visual>
      <origin
        xyz="0 0 0"
        rpy="0 0 0" />
      <geometry>
        <mesh
          filename="package://main_new_feet_no_arm_update_motor/meshes/head_p.STL" />
      </geometry>
      <material
        name="">
        <color
          rgba="0.89804 0.91765 0.92941 1" />
      </material>
    </visual>
    <collision>
      <origin
        xyz="0 0 0"
        rpy="0 0 0" />
      <geometry>
        <mesh
          filename="package://main_new_feet_no_arm_update_motor/meshes/head_p.STL" />
      </geometry>
    </collision>
  </link>
  <joint
    name="j_head_p"
    type="revolute">
    <origin
      xyz="0.0264999999999754 0 0.648964000000025"
      rpy="0 0 0" />
    <parent
      link="torso" />
    <child
      link="head_p" />
    <axis
      xyz="0 0 1" />
    <limit
      lower="-1.57"
      upper="1.57"
      effort="16"
      velocity="3" />
    <safety_controller
      k_velocity="0" />
  </joint>
  <link
    name="head_t">
    <inertial>
      <origin
        xyz="0.00024 0.0003 0.0127"
        rpy="0 0 0" />
      <mass
        value="0.07613" />
      <inertia
        ixx="2E-05"
        ixy="7.33E-13"
        ixz="1.74E-12"
        iyy="1.7E-05"
        iyz="3.01E-07"
        izz="1.23E-05" />
    </inertial>
    <visual>
      <origin
        xyz="0 0 0"
        rpy="0 0 0" />
      <geometry>
        <mesh
          filename="package://main_new_feet_no_arm_update_motor/meshes/head_t.STL" />
      </geometry>
      <material
        name="">
        <color
          rgba="0.752941176470588 0.752941176470588 0.752941176470588 1" />
      </material>
    </visual>
    <collision>
      <origin
        xyz="0 0 0"
        rpy="0 0 0" />
      <geometry>
        <mesh
          filename="package://main_new_feet_no_arm_update_motor/meshes/head_t.STL" />
      </geometry>
    </collision>
  </link>
  <joint
    name="j_head_t"
    type="revolute">
    <origin
      xyz="0 -0.000250000000001388 0"
      rpy="0 0 0" />
    <parent
      link="head_p" />
    <child
      link="head_t" />
    <axis
      xyz="0 1 0" />
    <limit
      lower="-1.57"
      upper="1.57"
      effort="16"
      velocity="3" />
    <safety_controller
      k_velocity="0" />
  </joint>
  <link
    name="leg_r_hip_y">
    <inertial>
      <origin
        xyz="-0.019 0 0.029685"
        rpy="0 0 0" />
      <mass
        value="0.031031" />
      <inertia
        ixx="7.47E-06"
        ixy="1.86E-20"
        ixz="-2E-20"
        iyy="4.57E-05"
        iyz="1.4E-20"
        izz="4.68E-05" />
    </inertial>
    <visual>
      <origin
        xyz="0 0 0"
        rpy="0 0 0" />
      <geometry>
        <mesh
          filename="package://main_new_feet_no_arm_update_motor/meshes/leg_r_hip_y.STL" />
      </geometry>
      <material
        name="">
        <color
          rgba="0.89804 0.91765 0.92941 1" />
      </material>
    </visual>
    <collision>
      <origin
        xyz="0 0 0"
        rpy="0 0 0" />
      <geometry>
        <mesh
          filename="package://main_new_feet_no_arm_update_motor/meshes/leg_r_hip_y.STL" />
      </geometry>
    </collision>
  </link>
  <joint
    name="j_leg_r_hip_y"
    type="revolute">
    <origin
      xyz="0.018999999999975 -0.0612500000000002 0.315000000000024"
      rpy="0 0 0" />
    <parent
      link="torso" />
    <child
      link="leg_r_hip_y" />
    <axis
      xyz="0 0 1" />
    <limit
      lower="-1.57"
      upper="1.57"
      effort="16"
      velocity="3" />
    <safety_controller
      k_velocity="0" />
  </joint>
  <link
    name="leg_r_hip_r">
    <inertial>
      <origin
        xyz="-0.0209 -0.00096 0.01844"
        rpy="0 0 0" />
      <mass
        value="0.32716" />
      <inertia
        ixx="0.00013415"
        ixy="3.42E-12"
        ixz="1.85E-06"
        iyy="0.00013269"
        iyz="1.88E-06"
        izz="8.36E-05" />
    </inertial>
    <visual>
      <origin
        xyz="0 0 0"
        rpy="0 0 0" />
      <geometry>
        <mesh
          filename="package://main_new_feet_no_arm_update_motor/meshes/leg_r_hip_r.STL" />
      </geometry>
      <material
        name="">
        <color
          rgba="0.75294 0.75294 0.75294 1" />
      </material>
    </visual>
    <collision>
      <origin
        xyz="0 0 0"
        rpy="0 0 0" />
      <geometry>
        <mesh
          filename="package://main_new_feet_no_arm_update_motor/meshes/leg_r_hip_r.STL" />
      </geometry>
    </collision>
  </link>
  <joint
    name="j_leg_r_hip_r"
    type="revolute">
    <origin
      xyz="0.000500000000000056 0 0"
      rpy="0 0 0" />
    <parent
      link="leg_r_hip_y" />
    <child
      link="leg_r_hip_r" />
    <axis
      xyz="1 0 0" />
    <limit
      lower="-1.57"
      upper="1.57"
      effort="16"
      velocity="3" />
    <safety_controller
      k_velocity="0" />
  </joint>
  <link
    name="leg_r_hip_p">
    <inertial>
      <origin
        xyz="-0.00016 -0.00155 -0.0983"
        rpy="0 0 0" />
      <mass
        value="0.187828259" />
      <inertia
        ixx="0.000102845"
        ixy="4.09E-09"
        ixz="-2.79E-08"
        iyy="7.48E-05"
        iyz="-1.87E-06"
        izz="5.88E-05" />
    </inertial>
    <visual>
      <origin
        xyz="0 0 0"
        rpy="0 0 0" />
      <geometry>
        <mesh
          filename="package://main_new_feet_no_arm_update_motor/meshes/leg_r_hip_p.STL" />
      </geometry>
      <material
        name="">
        <color
          rgba="0.752941176470588 0.752941176470588 0.752941176470588 1" />
      </material>
    </visual>
    <collision>
      <origin
        xyz="0 0 0"
        rpy="0 0 0" />
      <geometry>
        <mesh
          filename="package://main_new_feet_no_arm_update_motor/meshes/leg_r_hip_p.STL" />
      </geometry>
    </collision>
  </link>
  <joint
    name="j_leg_r_hip_p"
    type="revolute">
    <origin
      xyz="0 0 0"
      rpy="0 0 0" />
    <parent
      link="leg_r_hip_r" />
    <child
      link="leg_r_hip_p" />
    <axis
      xyz="0 -1 0" />
    <limit
      lower="-1.57"
      upper="1.57"
      effort="16"
      velocity="3" />
    <safety_controller
      k_velocity="0" />
  </joint>
  <link
    name="leg_r_knee">
    <inertial>
      <origin
        xyz="0 0 -0.072"
        rpy="0 0 0" />
      <mass
        value="0.047124436" />
      <inertia
        ixx="5.6E-05"
        ixy="-5.08E-21"
        ixz="1.68E-20"
        iyy="3.18E-05"
        iyz="2.72E-08"
        izz="3.15E-05" />
    </inertial>
    <visual>
      <origin
        xyz="0 0 0"
        rpy="0 0 0" />
      <geometry>
        <mesh
          filename="package://main_new_feet_no_arm_update_motor/meshes/leg_r_knee.STL" />
      </geometry>
      <material
        name="">
        <color
          rgba="0.752941176470588 0.752941176470588 0.752941176470588 1" />
      </material>
    </visual>
    <collision>
      <origin
        xyz="0 0 0"
        rpy="0 0 0" />
      <geometry>
        <mesh
          filename="package://main_new_feet_no_arm_update_motor/meshes/leg_r_knee.STL" />
      </geometry>
    </collision>
  </link>
  <joint
    name="j_leg_r_knee"
    type="revolute">
    <origin
      xyz="0 0 -0.126500000000018"
      rpy="0 0 0" />
    <parent
      link="leg_r_hip_p" />
    <child
      link="leg_r_knee" />
    <axis
      xyz="0 -1 0" />
    <limit
      lower="-3.14"
      upper="3.14"
      effort="16"
      velocity="3" />
    <safety_controller
      k_velocity="0" />
  </joint>
  <link
    name="leg_r_ankle_p">
    <inertial>
      <origin
        xyz="-0.021 -0.00083 0.0185"
        rpy="0 0 0" />
      <mass
        value="0.326972718" />
      <inertia
        ixx="0.000134144"
        ixy="-3.09E-12"
        ixz="-1.86E-06"
        iyy="0.000132683"
        iyz="-1.88E-06"
        izz="8.36E-05" />
    </inertial>
    <visual>
      <origin
        xyz="0 0 0"
        rpy="0 0 0" />
      <geometry>
        <mesh
          filename="package://main_new_feet_no_arm_update_motor/meshes/leg_r_ankle_p.STL" />
      </geometry>
      <material
        name="">
        <color
          rgba="0.752941176470588 0.752941176470588 0.752941176470588 1" />
      </material>
    </visual>
    <collision>
      <origin
        xyz="0 0 0"
        rpy="0 0 0" />
      <geometry>
        <mesh
          filename="package://main_new_feet_no_arm_update_motor/meshes/leg_r_ankle_p.STL" />
      </geometry>
    </collision>
  </link>
  <joint
    name="j_leg_r_ankle_p"
    type="revolute">
    <origin
      xyz="0 0 -0.144000000000011"
      rpy="0 0 0" />
    <parent
      link="leg_r_knee" />
    <child
      link="leg_r_ankle_p" />
    <axis
      xyz="0 1 0" />
    <limit
      lower="-1.57"
      upper="1.57"
      effort="16"
      velocity="3" />
    <safety_controller
      k_velocity="0" />
  </joint>
  <link
    name="leg_r_ankle_r">
    <inertial>
      <origin
        xyz="-0.0195 0 -0.037628795"
        rpy="0 0 0" />
      <mass
        value="0.110581864" />
      <inertia
        ixx="5.19E-05"
        ixy="-5.56E-11"
        ixz="-4.52E-20"
        iyy="0.000143529"
        iyz="-4.81E-20"
        izz="0.000188702" />
    </inertial>
    <visual>
      <origin
        xyz="0 0 0"
        rpy="0 0 0" />
      <geometry>
        <mesh
          filename="package://main_new_feet_no_arm_update_motor/meshes/leg_r_ankle_r.STL" />
      </geometry>
      <material
        name="">
        <color
          rgba="0.752941176470588 0.752941176470588 0.752941176470588 1" />
      </material>
    </visual>
    <collision>
      <origin
        xyz="0 0 0"
        rpy="0 0 0" />
      <geometry>
        <mesh
          filename="package://main_new_feet_no_arm_update_motor/meshes/leg_r_ankle_r.STL" />
      </geometry>
    </collision>
  </link>
  <joint
    name="j_leg_r_ankle_r"
    type="revolute">
    <origin
      xyz="0 0 0"
      rpy="0 0 0" />
    <parent
      link="leg_r_ankle_p" />
    <child
      link="leg_r_ankle_r" />
    <axis
      xyz="1 0 0" />
    <limit
      lower="-1.57"
      upper="1.57"
      effort="16"
      velocity="3" />
    <safety_controller
      k_velocity="0" />
  </joint>
  <link
    name="leg_l_hip_y">
    <inertial>
      <origin
        xyz="-0.019 0 0.029684933"
        rpy="0 0 0" />
      <mass
        value="0.031030679" />
      <inertia
        ixx="7.47E-06"
        ixy="-8.05E-21"
        ixz="-4.28E-20"
        iyy="4.57E-05"
        iyz="1.69E-20"
        izz="4.68E-05" />
    </inertial>
    <visual>
      <origin
        xyz="0 0 0"
        rpy="0 0 0" />
      <geometry>
        <mesh
          filename="package://main_new_feet_no_arm_update_motor/meshes/leg_l_hip_y.STL" />
      </geometry>
      <material
        name="">
        <color
          rgba="0.898039215686275 0.917647058823529 0.929411764705882 1" />
      </material>
    </visual>
    <collision>
      <origin
        xyz="0 0 0"
        rpy="0 0 0" />
      <geometry>
        <mesh
          filename="package://main_new_feet_no_arm_update_motor/meshes/leg_l_hip_y.STL" />
      </geometry>
    </collision>
  </link>
  <joint
    name="j_leg_l_hip_y"
    type="revolute">
    <origin
      xyz="0.018999999999975 0.06125 0.315000000000024"
      rpy="0 0 0" />
    <parent
      link="torso" />
    <child
      link="leg_l_hip_y" />
    <axis
      xyz="0 0 1" />
    <limit
      lower="-1.57"
      upper="1.57"
      effort="16"
      velocity="3" />
    <safety_controller
      k_velocity="0" />
  </joint>
  <link
    name="leg_l_hip_r">
    <inertial>
      <origin
        xyz="-0.0209 -0.00096 0.01844"
        rpy="0 0 0" />
      <mass
        value="0.327163614" />
      <inertia
        ixx="0.000134145"
        ixy="3.42E-12"
        ixz="1.85E-06"
        iyy="0.000132688"
        iyz="1.88E-06"
        izz="8.36E-05" />
    </inertial>
    <visual>
      <origin
        xyz="0 0 0"
        rpy="0 0 0" />
      <geometry>
        <mesh
          filename="package://main_new_feet_no_arm_update_motor/meshes/leg_l_hip_r.STL" />
      </geometry>
      <material
        name="">
        <color
          rgba="0.752941176470588 0.752941176470588 0.752941176470588 1" />
      </material>
    </visual>
    <collision>
      <origin
        xyz="0 0 0"
        rpy="0 0 0" />
      <geometry>
        <mesh
          filename="package://main_new_feet_no_arm_update_motor/meshes/leg_l_hip_r.STL" />
      </geometry>
    </collision>
  </link>
  <joint
    name="j_leg_l_hip_r"
    type="revolute">
    <origin
      xyz="0.000500000000000028 0 0"
      rpy="0 0 0" />
    <parent
      link="leg_l_hip_y" />
    <child
      link="leg_l_hip_r" />
    <axis
      xyz="1 0 0" />
    <limit
      lower="-1.57"
      upper="1.57"
      effort="16"
      velocity="3" />
    <safety_controller
      k_velocity="0" />
  </joint>
  <link
    name="leg_l_hip_p">
    <inertial>
      <origin
        xyz="-0.00016 -0.00155 -0.0983"
        rpy="0 0 0" />
      <mass
        value="0.187828259" />
      <inertia
        ixx="0.000102845"
        ixy="4.09E-09"
        ixz="-2.79E-08"
        iyy="7.48E-05"
        iyz="-1.87E-06"
        izz="5.88E-05" />
    </inertial>
    <visual>
      <origin
        xyz="0 0 0"
        rpy="0 0 0" />
      <geometry>
        <mesh
          filename="package://main_new_feet_no_arm_update_motor/meshes/leg_l_hip_p.STL" />
      </geometry>
      <material
        name="">
        <color
          rgba="0.752941176470588 0.752941176470588 0.752941176470588 1" />
      </material>
    </visual>
    <collision>
      <origin
        xyz="0 0 0"
        rpy="0 0 0" />
      <geometry>
        <mesh
          filename="package://main_new_feet_no_arm_update_motor/meshes/leg_l_hip_p.STL" />
      </geometry>
    </collision>
  </link>
  <joint
    name="j_leg_l_hip_p"
    type="revolute">
    <origin
      xyz="0 0 0"
      rpy="0 0 0" />
    <parent
      link="leg_l_hip_r" />
    <child
      link="leg_l_hip_p" />
    <axis
      xyz="0 -1 0" />
    <limit
      lower="-1.57"
      upper="1.57"
      effort="16"
      velocity="3" />
    <safety_controller
      k_velocity="0" />
  </joint>
  <link
    name="leg_l_knee">
    <inertial>
      <origin
        xyz="0 0 -0.072"
        rpy="0 0 0" />
      <mass
        value="0.047124436" />
      <inertia
        ixx="5.6E-05"
        ixy="9.32E-21"
        ixz="-3.07E-21"
        iyy="3.18E-05"
        iyz="2.72E-08"
        izz="3.15E-05" />
    </inertial>
    <visual>
      <origin
        xyz="0 0 0"
        rpy="0 0 0" />
      <geometry>
        <mesh
          filename="package://main_new_feet_no_arm_update_motor/meshes/leg_l_knee.STL" />
      </geometry>
      <material
        name="">
        <color
          rgba="0.752941176470588 0.752941176470588 0.752941176470588 1" />
      </material>
    </visual>
    <collision>
      <origin
        xyz="0 0 0"
        rpy="0 0 0" />
      <geometry>
        <mesh
          filename="package://main_new_feet_no_arm_update_motor/meshes/leg_l_knee.STL" />
      </geometry>
    </collision>
  </link>
  <joint
    name="j_leg_l_knee"
    type="revolute">
    <origin
      xyz="0 0 -0.126499999999996"
      rpy="0 0 0" />
    <parent
      link="leg_l_hip_p" />
    <child
      link="leg_l_knee" />
    <axis
      xyz="0 -1 0" />
    <limit
      lower="-3.14"
      upper="3.14"
      effort="16"
      velocity="3" />
    <safety_controller
      k_velocity="0" />
  </joint>
  <link
    name="leg_l_ankle_p">
    <inertial>
      <origin
        xyz="-0.021 -0.00083 0.0185"
        rpy="0 0 0" />
      <mass
        value="0.326972718" />
      <inertia
        ixx="0.000134144"
        ixy="-3.09E-12"
        ixz="-1.86E-06"
        iyy="0.000132683"
        iyz="-1.88E-06"
        izz="8.36E-05" />
    </inertial>
    <visual>
      <origin
        xyz="0 0 0"
        rpy="0 0 0" />
      <geometry>
        <mesh
          filename="package://main_new_feet_no_arm_update_motor/meshes/leg_l_ankle_p.STL" />
      </geometry>
      <material
        name="">
        <color
          rgba="0.752941176470588 0.752941176470588 0.752941176470588 1" />
      </material>
    </visual>
    <collision>
      <origin
        xyz="0 0 0"
        rpy="0 0 0" />
      <geometry>
        <mesh
          filename="package://main_new_feet_no_arm_update_motor/meshes/leg_l_ankle_p.STL" />
      </geometry>
    </collision>
  </link>
  <joint
    name="j_leg_l_ankle_p"
    type="revolute">
    <origin
      xyz="0 0 -0.144000000000011"
      rpy="0 0 0" />
    <parent
      link="leg_l_knee" />
    <child
      link="leg_l_ankle_p" />
    <axis
      xyz="0 1 0" />
    <limit
      lower="-1.57"
      upper="1.57"
      effort="16"
      velocity="3" />
    <safety_controller
      k_velocity="0" />
  </joint>
  <link
    name="leg_l_ankle_r">
    <inertial>
      <origin
        xyz="-0.0195 0 -0.037628795"
        rpy="0 0 0" />
      <mass
        value="0.110581864" />
      <inertia
        ixx="5.19E-05"
        ixy="-5.56E-11"
        ixz="-6.14E-20"
        iyy="0.000143529"
        iyz="1.09E-20"
        izz="0.000188702" />
    </inertial>
    <visual>
      <origin
        xyz="0 0 0"
        rpy="0 0 0" />
      <geometry>
        <mesh
          filename="package://main_new_feet_no_arm_update_motor/meshes/leg_l_ankle_r.STL" />
      </geometry>
      <material
        name="">
        <color
          rgba="0.752941176470588 0.752941176470588 0.752941176470588 1" />
      </material>
    </visual>
    <collision>
      <origin
        xyz="0 0 0"
        rpy="0 0 0" />
      <geometry>
        <mesh
          filename="package://main_new_feet_no_arm_update_motor/meshes/leg_l_ankle_r.STL" />
      </geometry>
    </collision>
  </link>
  <joint
    name="j_leg_l_ankle_r"
    type="revolute">
    <origin
      xyz="0 0 0"
      rpy="0 0 0" />
    <parent
      link="leg_l_ankle_p" />
    <child
      link="leg_l_ankle_r" />
    <axis
      xyz="1 0 0" />
    <limit
      lower="-1.57"
      upper="1.57"
      effort="16"
      velocity="3" />
    <safety_controller
      k_velocity="0" />
  </joint>
</robot>